Workbook

Sheet Colaboradores_Dados
A1: ID do Colaborador | B1: Data de Entrada na Empresa | C1: Data de Saída | D1: Data de Nascimento | E1: Género | F1: Polo | G1: Área | H1: Função | I1: Carga Horária Semanal no Contrato (h) | J1: Carga Horária Média Semanal Trabalhada (h) | K1: Nº de Projetos Realizados | L1: Foi Promovido Durante o Último Ano?
A2: 1 | B2: 45231 | C2: N/A | D2: 35646 | E2: F | F2: Setúbal | G2: 2 | H2: 1 | I2: 35 | J2: 37 | K2: 7 | L2: 0
A3: 2 | B3: 45482 | C3: 45659 | D3: 22713 | E3: F | F3: Porto | G3: 3 | H3: 1 | I3: 35 | J3: 40 | K3: 6 | L3: 0
A4: 3 | B4: 45502 | C4: N/A | D4: 28712 | E4: F | F4: Lisboa | G4: 3 | H4: 1 | I4: 35 | J4: 37 | K4: 3 | L4: 0
A5: 4 | B5: 46004 | C5: N/A | D5: 34071 | E5: M | F5: Lisboa | G5: 5 | H5: 1 | I5: 45 | J5: 52 | K5: 5 | L5: 0
A6: 5 | B6: 45558 | C6: N/A | D6: 29654 | E6: M | F6: Porto | G6: 2 | H6: 1 | I6: 35 | J6: 33 | K6: 8 | L6: 0
A7: 6 | B7: 44422 | C7: 44902 | D7: 28068 | E7: F | F7: Faro | G7: 4 | H7: 1 | I7: 35 | J7: 36 | K7: 3 | L7: 0
A8: 7 | B8: 45881 | C8: 46015 | D8: 37544 | E8: F | F8: Porto | G8: 3 | H8: 1 | I8: 40 | J8: 48 | K8: 4 | L8: 0
A9: 8 | B9: 44222 | C9: 44772 | D9: 24278 | E9: F | F9: Faaro | G9: 1 | H9: 1 | I9: 45 | J9: 48 | K9: 8 | L9: 0
A10: 9 | B10: 44832 | C10: 45908 | D10: 33477 | E10: F | F10: Poro | G10: 5 | H10: 1 | I10: 40 | J10: 39 | K10: 11 | L10: 0
A11: 10 | B11: 45506 | C11: N/A | D11: 25691 | E11: M | F11: Lisboa | G11: 1 | H11: 3 | I11: 40 | J11: 43 | K11: 3 | L11: 1
A12: 11 | B12: 44902 | C12: 45734 | D12: 26790 | E12: F | F12: Setúbal | G12: 4 | H12: 1 | I12: 45 | J12: 49 | K12: 6 | L12: 1
A13: 12 | B13: 44824 | C13: 45018 | D13: 33714 | E13: M | F13: Lisboa | G13: 5 | H13: 1 | I13: 45 | J13: 52 | K13: 12 | L13: 0
A14: 13 | B14: 45510 | C14: N/A | D14: 35367 | E14: F | F14: Setúbal | G14: 4 | H14: 2 | I14: 45 | J14: 49 | K14: 9 | L14: 1
A15: 14 | B15: 45444 | C15: N/A | D15: 32998 | E15: F | F15: Lisboa | G15: 4 | H15: 2 | I15: 45 | J15: 44 | K15: 2 | L15: 0
A16: 15 | B16: 45820 | C16: N/A | D16: 31873 | E16: F | F16: Lisboa | G16: 4 | H16: 1 | I16: 45 | J16: 39 | K16: 10 | L16: 0
A17: 16 | B17: 45102 | C17: 45288 | D17: 32905 | E17: M | F17: Setúbal | G17: 5 | H17: 1 | I17: 40 | J17: 46 | K17: 9 | L17: 0
A18: 17 | B18: 44990 | C18: 45496 | D18: 27400 | E18: M | F18: Liboa | G18: 2 | H18: 2 | I18: 40 | J18: 45 | K18: 2 | L18: 0
A19: 18 | B19: 44437 | C19: 45637 | D19: 27704 | E19: M | F19: Faro | G19: 4 | H19: 1 | I19: 40 | J19: 43 | K19: 7 | L19: 0
A20: 19 | B20: 45292 | C20: 45768 | D20: 32669 | E20: F | F20: Lisboa | G20: 4 | H20: 3 | I20: 35 | J20: 41 | K20: 8 | L20: 0
A21: 20 | B21: 45070 | C21: 45540 | D21: 29931 | E21: M | F21: Faro | G21: 5 | H21: 3 | I21: 45 | J21: 46 | K21: 6 | L21: 0
A22: 21 | B22: 45923 | C22: N/A | D22: 29340 | E22: F | F22: Lisboa | G22: 5 | H22: 2 | I22: 40 | J22: 47 | K22: 4 | L22: 0
A23: 22 | B23: 45584 | C23: 45900 | D23: 34025 | E23: M | F23: Lisboa | G23: 1 | H23: 3 | I23: 40 | J23: 39 | K23: 9 | L23: 1
A24: 23 | B24: 44928 | C24: 45825 | D24: 33020 | E24: M | F24: Setúbal | G24: 3 | H24: 1 | I24: 40 | J24: 37 | K24: 5 | L24: 1
A25: 24 | B25: 44661 | C25: 45016 | D25: 32905 | E25: M | F25: Lis | G25: 2 | H25: 1 | I25: 40 | J25: 40 | K25: 7 | L25: 1
A26: 25 | B26: 45925 | C26: N/A | D26: 34414 | E26: F | F26: Lisboa | G26: 4 | H26: 2 | I26: 35 | J26: 39 | K26: 7 | L26: 0
A27: 26 | B27: 44828 | C27: 45239 | D27: 33865 | E27: F | F27: Lisboa | G27: 4 | H27: 1 | I27: 40 | J27: 42 | K27: 9 | L27: 0
A28: 27 | B28: 45739 | C28: N/A | D28: 32677 | E28: F | F28: Lisboa | G28: 4 | H28: 1 | I28: 40 | J28: 43 | K28: 6 | L28: 1
A29: 28 | B29: 45441 | C29: 45509 | D29: 32495 | E29: F | F29: Lisboa | G29: 5 | H29: 3 | I29: 35 | J29: 46 | K29: 5 | L29: 0
A30: 29 | B30: 44860 | C30: 45373 | D30: 35410 | E30: M | F30: Set | G30: 5 | H30: 2 | I30: 35 | J30: 42 | K30: 7 | L30: 0
A31: 30 | B31: 44761 | C31: 45596 | D31: 33244 | E31: F | F31: Faro | G31: 4 | H31: 3 | I31: 40 | J31: 46 | K31: 10 | L31: 1
A32: 31 | B32: 44922 | C32: 45740 | D32: 28475 | E32: M | F32: Lisboa | G32: 4 | H32: 3 | I32: 35 | J32: 42 | K32: 8 | L32: 0
A33: 32 | B33: 46014 | C33: N/A | D33: 28383 | E33: M | F33: Setúbal | G33: 5 | H33: 1 | I33: 40 | J33: 46 | K33: 6 | L33: 0
A34: 33 | B34: 45801 | C34: 45999 | D34: 33429 | E34: F | F34: Setúbal | G34: 4 | H34: 2 | I34: 40 | J34: 43 | K34: 2 | L34: 0
A35: 34 | B35: 45047 | C35: 45685 | D35: 31795 | E35: F | F35: Lisboa | G35: 4 | H35: 1 | I35: 35 | J35: 36 | K35: 11 | L35: 0
A36: 35 | B36: 45716 | C36: N/A | D36: 29628 | E36: F | F36: Porto | G36: 2 | H36: 2 | I36: 45 | J36: 49 | K36: 10 | L36: 0
A37: 36 | B37: 44652 | C37: 45923 | D37: 35348 | E37: F | F37: Porto | G37: 1 | H37: 2 | I37: 40 | J37: 41 | K37: 3 | L37: 1
A38: 37 | B38: 45634 | C38: N/A | D38: 27025 | E38: F | F38: Setúbal | G38: 4 | H38: 1 | I38: 35 | J38: 37 | K38: 11 | L38: 0
A39: 38 | B39: 45274 | C39: N/A | D39: 32804 | E39: M | F39: Faro | G39: 2 | H39: 1 | I39: 40 | J39: 45 | K39: 3 | L39: 0
A40: 39 | B40: 45979 | C40: N/A | D40: 32045 | E40: F | F40: Porto | G40: 3 | H40: 1 | I40: 45 | J40: 51 | K40: 3 | L40: 0
...

Sheet Colaboradores_Avaliação
A1: ID do Colaborador | B1: Avaliação de Desempenho pelo Responsável | C1: Autoavaliação do Desempenho | D1: Nível de Bem-Estar na Empresa | E1: Nível de Stress
A2: 1 | B2: 4 | C2: 1 | D2: 2 | E2: 4
A3: 2 | B3: 3 | C3: 5 | D3: 3 | E3: 3
A4: 3 | B4: 3 | C4: 3 | D4: 3 | E4: 3
A5: 4 | B5: 3 | C5: 3 | D5: 2 | E5: 4
A6: 5 | B6: 5 | C6: 5 | D6: 3 | E6: 4
A7: 6 | B7: 3 | C7: 4 | D7: 5 | E7: 4
A8: 7 | B8: 1 | C8: 3 | D8: 2 | E8: 2
A9: 8 | B9: 3 | C9: 3 | D9: 4 | E9: 5
A10: 9 | B10: 4 | C10: 4 | D10: 1 | E10: 5
A11: 10 | B11: 5 | C11: 3 | D11: 5 | E11: 3
A12: 11 | B12: 4 | C12: 3 | D12: 4 | E12: 2
A13: 12 | B13: 3 | C13: 4 | D13: 1 | E13: 5
... A10001: 10000 | B10001: 3 | C10001: 2 | D10001: 2 | E10001: 5

Sheet Códigos
B2: Género | C2: Código
B3: Feminino | C3: F
B4: Masculino | C4: M
B6: Área | C6: Código
B7: Administrativa | C7: 1
B8: Comunicação | C8: 2
B9: Financeira | C9: 3
B10: Operações | C10: 4
B11: Vendas | C11: 5
B13: Função | C13: Código
B14: Junior | C14: 1
B15: Senior | C15: 2
B16: Manager | C16: 3
B18: Foi Promovido Durante o Último Ano? | C18: Código
B19: Não | C19: 0
B20: Sim | C20: 1
B22: Avaliação de Desempenho pelo Responsável | C22: Código
B23: Muito abaixo do esperado | C23: 1
B24: Abaixo do esperado | C24: 2
B25: Dentro do esperado | C25: 3
B26: Acima do esperado | C26: 4
B27: Excelente | C27: 5
B29: Autoavaliação do Desempenho | C29: Código
B30: Muito abaixo do esperado | C30: 1
B31: Abaixo do esperado | C31: 2
B32: Dentro do esperado | C32: 3
B33: Acima do esperado | C33: 4
B34: Excelente | C34: 5
B36: Nível de Bem-Estar na Empresa | C36: Código
B37: Muito baixo | C37: 1
B38: Baixo | C38: 2
B39: Moderado | C39: 3
B40: Alto | C40: 4
B41: Muito alto | C41: 5
B43: Nível de Stress | C43: Código
B44: Muito baixo | C44: 1
B45: Baixo | C45: 2
B46: Moderado | C46: 3
B47: Alto | C47: 4
B48: Muito alto | C48: 5

Sheet Calc_Correl
A1: ID | B1: Polo | C1: Área | D1: Equipa | E1: Performance | F1: Stress | G1: Bem-estar | H1: Horas_Contrato | I1: Horas_Trabalhadas | J1: Sobrecarga_Horária | K1: Data_Entrada | L1: Data_Saída | M1: Antiguidade_anos | N1: Ativo
A2: =Colaboradores_Dados!A2 -> 1 | B2: =Colaboradores_Dados!F2 -> Setúbal | C2: =Colaboradores_Dados!G2 -> 2 | D2: =B2&" - Área "&C2 -> Setúbal - Área 2 | E2: =Colaboradores_Avaliação!B2 -> 4 | F2: =Colaboradores_Avaliação!E2 -> 4 | G2: =Colaboradores_Avaliação!D2 -> 2 | H2: =Colaboradores_Dados!I2 -> 35 | I2: =Colaboradores_Dados!J2 -> 37 | J2: =I2-H2 -> 2 | K2: =Colaboradores_Dados!B2 -> 45231 | L2: =Colaboradores_Dados!C2 -> N/A | M2: =(IF(OR(L2="",L2="N/A"),DATE(2025,12,31),L2)-K2)/365.25 -> 2.16564 | N2: =IF(OR(L2="",L2="N/A"),1,0) -> 1
A3: =Colaboradores_Dados!A3 -> 2 | B3: =Colaboradores_Dados!F3 -> Porto | C3: =Colaboradores_Dados!G3 -> 3 | D3: =B3&" - Área "&C3 -> Porto - Área 3 | E3: =Colaboradores_Avaliação!B3 -> 3 | F3: =Colaboradores_Avaliação!E3 -> 3 | G3: =Colaboradores_Avaliação!D3 -> 3 | H3: =Colaboradores_Dados!I3 -> 35 | I3: =Colaboradores_Dados!J3 -> 40 | J3: =I3-H3 -> 5 | K3: =Colaboradores_Dados!B3 -> 45482 | L3: =Colaboradores_Dados!C3 -> 45659 | M3: =(IF(OR(L3="",L3="N/A"),DATE(2025,12,31),L3)-K3)/365.25 -> 0.48459959 | N3: =IF(OR(L3="",L3="N/A"),1,0) -> 0
A4: =Colaboradores_Dados!A4 -> 3 | B4: =Colaboradores_Dados!F4 -> Lisboa | C4: =Colaboradores_Dados!G4 -> 3 | D4: =B4&" - Área "&C4 -> Lisboa - Área 3 | E4: =Colaboradores_Avaliação!B4 -> 3 | F4: =Colaboradores_Avaliação!E4 -> 3 | G4: =Colaboradores_Avaliação!D4 -> 3 | H4: =Colaboradores_Dados!I4 -> 35 | I4: =Colaboradores_Dados!J4 -> 37 | J4: =I4-H4 -> 2 | K4: =Colaboradores_Dados!B4 -> 45502 | L4: =Colaboradores_Dados!C4 -> N/A | M4: =(IF(OR(L4="",L4="N/A"),DATE(2025,12,31),L4)-K4)/365.25 -> 1.4236824 | N4: =IF(OR(L4="",L4="N/A"),1,0) -> 1
A5: =Colaboradores_Dados!A5 -> 4 | B5: =Colaboradores_Dados!F5 -> Lisboa | C5: =Colaboradores_Dados!G5 -> 5 | D5: =B5&" - Área "&C5 -> Lisboa - Área 5 | E5: =Colaboradores_Avaliação!B5 -> 3 | F5: =Colaboradores_Avaliação!E5 -> 4 | G5: =Colaboradores_Avaliação!D5 -> 2 | H5: =Colaboradores_Dados!I5 -> 45 | I5: =Colaboradores_Dados!J5 -> 52 | J5: =I5-H5 -> 7 | K5: =Colaboradores_Dados!B5 -> 46004 | L5: =Colaboradores_Dados!C5 -> N/A | M5: =(IF(OR(L5="",L5="N/A"),DATE(2025,12,31),L5)-K5)/365.25 -> 0.049281314 | N5: =IF(OR(L5="",L5="N/A"),1,0) -> 1
A6: =Colaboradores_Dados!A6 -> 5 | B6: =Colaboradores_Dados!F6 -> Porto | C6: =Colaboradores_Dados!G6 -> 2 | D6: =B6&" - Área "&C6 -> Porto - Área 2 | E6: =Colaboradores_Avaliação!B6 -> 5 | F6: =Colaboradores_Avaliação!E6 -> 4 | G6: =Colaboradores_Avaliação!D6 -> 3 | H6: =Colaboradores_Dados!I6 -> 35 | I6: =Colaboradores_Dados!J6 -> 33 | J6: =I6-H6 -> -2 | K6: =Colaboradores_Dados!B6 -> 45558 | L6: =Colaboradores_Dados!C6 -> N/A | M6: =(IF(OR(L6="",L6="N/A"),DATE(2025,12,31),L6)-K6)/365.25 -> 1.2703628 | N6: =IF(OR(L6="",L6="N/A"),1,0) -> 1
A7: =Colaboradores_Dados!A7 -> 6 | B7: =Colaboradores_Dados!F7 -> Faro | C7: =Colaboradores_Dados!G7 -> 4 | D7: =B7&" - Área "&C7 -> Faro - Área 4 | E7: =Colaboradores_Avaliação!B7 -> 3 | F7: =Colaboradores_Avaliação!E7 -> 4 | G7: =Colaboradores_Avaliação!D7 -> 5 | H7: =Colaboradores_Dados!I7 -> 35 | I7: =Colaboradores_Dados!J7 -> 36 | J7: =I7-H7 -> 1 | K7: =Colaboradores_Dados!B7 -> 44422 | L7: =Colaboradores_Dados!C7 -> 44902 | M7: =(IF(OR(L7="",L7="N/A"),DATE(2025,12,31),L7)-K7)/365.25 -> 1.3141684 | N7: =IF(OR(L7="",L7="N/A"),1,0) -> 0
A8: =Colaboradores_Dados!A8 -> 7 | B8: =Colaboradores_Dados!F8 -> Porto | C8: =Colaboradores_Dados!G8 -> 3 | D8: =B8&" - Área "&C8 -> Porto - Área 3 | E8: =Colaboradores_Avaliação!B8 -> 1 | F8: =Colaboradores_Avaliação!E8 -> 2 | G8: =Colaboradores_Avaliação!D8 -> 2 | H8: =Colaboradores_Dados!I8 -> 40 | I8: =Colaboradores_Dados!J8 -> 48 | J8: =I8-H8 -> 8 | K8: =Colaboradores_Dados!B8 -> 45881 | L8: =Colaboradores_Dados!C8 -> 46015 | M8: =(IF(OR(L8="",L8="N/A"),DATE(2025,12,31),L8)-K8)/365.25 -> 0.36687201 | N8: =IF(OR(L8="",L8="N/A"),1,0) -> 0
A9: =Colaboradores_Dados!A9 -> 8 | B9: =Colaboradores_Dados!F9 -> Faaro | C9: =Colaboradores_Dados!G9 -> 1 | D9: =B9&" - Área "&C9 -> Faaro - Área 1 | E9: =Colaboradores_Avaliação!B9 -> 3 | F9: =Colaboradores_Avaliação!E9 -> 5 | G9: =Colaboradores_Avaliação!D9 -> 4 | H9: =Colaboradores_Dados!I9 -> 45 | I9: =Colaboradores_Dados!J9 -> 48 | J9: =I9-H9 -> 3 | K9: =Colaboradores_Dados!B9 -> 44222 | L9: =Colaboradores_Dados!C9 -> 44772 | M9: =(IF(OR(L9="",L9="N/A"),DATE(2025,12,31),L9)-K9)/365.25 -> 1.5058179 | N9: =IF(OR(L9="",L9="N/A"),1,0) -> 0
A10: =Colaboradores_Dados!A10 -> 9 | B10: =Colaboradores_Dados!F10 -> Poro | C10: =Colaboradores_Dados!G10 -> 5 | D10: =B10&" - Área "&C10 -> Poro - Área 5 | E10: =Colaboradores_Avaliação!B10 -> 4 | F10: =Colaboradores_Avaliação!E10 -> 5 | G10: =Colaboradores_Avaliação!D10 -> 1 | H10: =Colaboradores_Dados!I10 -> 40 | I10: =Colaboradores_Dados!J10 -> 39 | J10: =I10-H10 -> -1 | K10: =Colaboradores_Dados!B10 -> 44832 | L10: =Colaboradores_Dados!C10 -> 45908 | M10: =(IF(OR(L10="",L10="N/A"),DATE(2025,12,31),L10)-K10)/365.25 -> 2.9459274 | N10: =IF(OR(L10="",L10="N/A"),1,0) -> 0
A11: =Colaboradores_Dados!A11 -> 10 | B11: =Colaboradores_Dados!F11 -> Lisboa | C11: =Colaboradores_Dados!G11 -> 1 | D11: =B11&" - Área "&C11 -> Lisboa - Área 1 | E11: =Colaboradores_Avaliação!B11 -> 5 | F11: =Colaboradores_Avaliação!E11 -> 3 | G11: =Colaboradores_Avaliação!D11 -> 5 | H11: =Colaboradores_Dados!I11 -> 40 | I11: =Colaboradores_Dados!J11 -> 43 | J11: =I11-H11 -> 3 | K11: =Colaboradores_Dados!B11 -> 45506 | L11: =Colaboradores_Dados!C11 -> N/A | M11: =(IF(OR(L11="",L11="N/A"),DATE(2025,12,31),L11)-K11)/365.25 -> 1.412731 | N11: =IF(OR(L11="",L11="N/A"),1,0) -> 1
A12: =Colaboradores_Dados!A12 -> 11 | B12: =Colaboradores_Dados!F12 -> Setúbal | C12: =Colaboradores_Dados!G12 -> 4 | D12: =B12&" - Área "&C12 -> Setúbal - Área 4 | E12: =Colaboradores_Avaliação!B12 -> 4 | F12: =Colaboradores_Avaliação!E12 -> 2 | G12: =Colaboradores_Avaliação!D12 -> 4 | H12: =Colaboradores_Dados!I12 -> 45 | I12: =Colaboradores_Dados!J12 -> 49 | J12: =I12-H12 -> 4 | K12: =Colaboradores_Dados!B12 -> 44902 | L12: =Colaboradores_Dados!C12 -> 45734 | M12: =(IF(OR(L12="",L12="N/A"),DATE(2025,12,31),L12)-K12)/365.25 -> 2.2778919 | N12: =IF(OR(L12="",L12="N/A"),1,0) -> 0
A13: =Colaboradores_Dados!A13 -> 12 | B13: =Colaboradores_Dados!F13 -> Lisboa | C13: =Colaboradores_Dados!G13 -> 5 | D13: =B13&" - Área "&C13 -> Lisboa - Área 5 | E13: =Colaboradores_Avaliação!B13 -> 3 | F13: =Colaboradores_Avaliação!E13 -> 5 | G13: =Colaboradores_Avaliação!D13 -> 1 | H13: =Colaboradores_Dados!I13 -> 45 | I13: =Colaboradores_Dados!J13 -> 52 | J13: =I13-H13 -> 7 | K13: =Colaboradores_Dados!B13 -> 44824 | L13: =Colaboradores_Dados!C13 -> 45018 | M13: =(IF(OR(L13="",L13="N/A"),DATE(2025,12,31),L13)-K13)/365.25 -> 0.53114305 | N13: =IF(OR(L13="",L13="N/A"),1,0) -> 0
... A10001: =Colaboradores_Dados!A10001 -> 10000 | B10001: =Colaboradores_Dados!F10001 -> Faro | C10001: =Colaboradores_Dados!G10001 -> 3 | D10001: =B10001&" - Área "&C10001 -> Faro - Área 3 | E10001: =Colaboradores_Avaliação!B10001 -> 3 | F10001: =Colaboradores_Avaliação!E10001 -> 5 | G10001: =Colaboradores_Avaliação!D10001 -> 2 | H10001: =Colaboradores_Dados!I10001 -> 45 | I10001: =Colaboradores_Dados!J10001 -> 52 | J10001: =I10001-H10001 -> 7 | K10001: =Colaboradores_Dados!B10001 -> 45875 | L10001: =Colaboradores_Dados!C10001 -> N/A | M10001: =(IF(OR(L10001="",L10001="N/A"),DATE(2025,12,31),L10001)-K10001)/365.25 -> 0.40246407 | N10001: =IF(OR(L10001="",L10001="N/A"),1,0) -> 1
